Workbook

Sheet Summary
A1: check | B1: severity | C1: title | D1: hits:archon-search | E1: hits:moonset | F1: hits:financialwell | G1: hits:dddd | H1: hits:udemy-top-down-shooter | I1: hits total | J1: adjudicated | K1: TP | L1: FP | M1: precision % | N1: LLM-only found | O1: overlap w/ script | P1: script misses | Q1: script coverage % | R1: est. true hits
A2: arch-02 | B2: Major | C2: Use Case Depending on Framework Type | D2: =COUNTIFS(data_hits!$A:$A,"archon-search",data_hits!$C:$C,$A2) | E2: =COUNTIFS(data_hits!$A:$A,"moonset",data_hits!$C:$C,$A2) | F2: =COUNTIFS(data_hits!$A:$A,"financialwell",data_hits!$C:$C,$A2) | G2: =COUNTIFS(data_hits!$A:$A,"dddd",data_hits!$C:$C,$A2) | H2: =COUNTIFS(data_hits!$A:$A,"udemy-top-down-shooter",data_hits!$C:$C,$A2) | I2: =SUM(D2:H2) | J2: =K2+L2 | K2: =COUNTIFS(data_adj!$C:$C,$A2,data_adj!$E:$E,"TP") | L2: =COUNTIFS(data_adj!$C:$C,$A2,data_adj!$E:$E,"FP") | M2: =IF(J2=0,"",ROUND(100*K2/J2,1)) | N2: =COUNTIFS(data_llm!$C:$C,$A2) | O2: =COUNTIFS(data_llm!$C:$C,$A2,data_llm!$F:$F,TRUE) | P2: =N2-O2 | Q2: =IF(N2=0,"",ROUND(100*O2/N2,1)) | R2: =IF(J2=0,"",ROUND(I2*K2/J2,0))
A3: arch-03 | B3: Major | C3: Domain Entity with ORM Annotations | D3: =COUNTIFS(data_hits!$A:$A,"archon-search",data_hits!$C:$C,$A3) | E3: =COUNTIFS(data_hits!$A:$A,"moonset",data_hits!$C:$C,$A3) | F3: =COUNTIFS(data_hits!$A:$A,"financialwell",data_hits!$C:$C,$A3) | G3: =COUNTIFS(data_hits!$A:$A,"dddd",data_hits!$C:$C,$A3) | H3: =COUNTIFS(data_hits!$A:$A,"udemy-top-down-shooter",data_hits!$C:$C,$A3) | I3: =SUM(D3:H3) | J3: =K3+L3 | K3: =COUNTIFS(data_adj!$C:$C,$A3,data_adj!$E:$E,"TP") | L3: =COUNTIFS(data_adj!$C:$C,$A3,data_adj!$E:$E,"FP") | M3: =IF(J3=0,"",ROUND(100*K3/J3,1)) | N3: =COUNTIFS(data_llm!$C:$C,$A3) | O3: =COUNTIFS(data_llm!$C:$C,$A3,data_llm!$F:$F,TRUE) | P3: =N3-O3 | Q3: =IF(N3=0,"",ROUND(100*O3/N3,1)) | R3: =IF(J3=0,"",ROUND(I3*K3/J3,0))
A4: arch-05 | B4: Major | C4: Infrastructure Exception Leaking | D4: =COUNTIFS(data_hits!$A:$A,"archon-search",data_hits!$C:$C,$A4) | E4: =COUNTIFS(data_hits!$A:$A,"moonset",data_hits!$C:$C,$A4) | F4: =COUNTIFS(data_hits!$A:$A,"financialwell",data_hits!$C:$C,$A4) | G4: =COUNTIFS(data_hits!$A:$A,"dddd",data_hits!$C:$C,$A4) | H4: =COUNTIFS(data_hits!$A:$A,"udemy-top-down-shooter",data_hits!$C:$C,$A4) | I4: =SUM(D4:H4) | J4: =K4+L4 | K4: =COUNTIFS(data_adj!$C:$C,$A4,data_adj!$E:$E,"TP") | L4: =COUNTIFS(data_adj!$C:$C,$A4,data_adj!$E:$E,"FP") | M4: =IF(J4=0,"",ROUND(100*K4/J4,1)) | N4: =COUNTIFS(data_llm!$C:$C,$A4) | O4: =COUNTIFS(data_llm!$C:$C,$A4,data_llm!$F:$F,TRUE) | P4: =N4-O4 | Q4: =IF(N4=0,"",ROUND(100*O4/N4,1)) | R4: =IF(J4=0,"",ROUND(I4*K4/J4,0))
A5: arch-08 | B5: Major | C5: Service Locator / Magic Container | D5: =COUNTIFS(data_hits!$A:$A,"archon-search",data_hits!$C:$C,$A5) | E5: =COUNTIFS(data_hits!$A:$A,"moonset",data_hits!$C:$C,$A5) | F5: =COUNTIFS(data_hits!$A:$A,"financialwell",data_hits!$C:$C,$A5) | G5: =COUNTIFS(data_hits!$A:$A,"dddd",data_hits!$C:$C,$A5) | H5: =COUNTIFS(data_hits!$A:$A,"udemy-top-down-shooter",data_hits!$C:$C,$A5) | I5: =SUM(D5:H5) | J5: =K5+L5 | K5: =COUNTIFS(data_adj!$C:$C,$A5,data_adj!$E:$E,"TP") | L5: =COUNTIFS(data_adj!$C:$C,$A5,data_adj!$E:$E,"FP") | M5: =IF(J5=0,"",ROUND(100*K5/J5,1)) | N5: =COUNTIFS(data_llm!$C:$C,$A5) | O5: =COUNTIFS(data_llm!$C:$C,$A5,data_llm!$F:$F,TRUE) | P5: =N5-O5 | Q5: =IF(N5=0,"",ROUND(100*O5/N5,1)) | R5: =IF(J5=0,"",ROUND(I5*K5/J5,0))
A6: arch-09 | B6: Moderate | C6: Environment-Specific Branching in Business Logic | D6: =COUNTIFS(data_hits!$A:$A,"archon-search",data_hits!$C:$C,$A6) | E6: =COUNTIFS(data_hits!$A:$A,"moonset",data_hits!$C:$C,$A6) | F6: =COUNTIFS(data_hits!$A:$A,"financialwell",data_hits!$C:$C,$A6) | G6: =COUNTIFS(data_hits!$A:$A,"dddd",data_hits!$C:$C,$A6) | H6: =COUNTIFS(data_hits!$A:$A,"udemy-top-down-shooter",data_hits!$C:$C,$A6) | I6: =SUM(D6:H6) | J6: =K6+L6 | K6: =COUNTIFS(data_adj!$C:$C,$A6,data_adj!$E:$E,"TP") | L6: =COUNTIFS(data_adj!$C:$C,$A6,data_adj!$E:$E,"FP") | M6: =IF(J6=0,"",ROUND(100*K6/J6,1)) | N6: =COUNTIFS(data_llm!$C:$C,$A6) | O6: =COUNTIFS(data_llm!$C:$C,$A6,data_llm!$F:$F,TRUE) | P6: =N6-O6 | Q6: =IF(N6=0,"",ROUND(100*O6/N6,1)) | R6: =IF(J6=0,"",ROUND(I6*K6/J6,0))
A7: arch-11 | B7: Moderate | C7: Environment Address Hardcoded in Code | D7: =COUNTIFS(data_hits!$A:$A,"archon-search",data_hits!$C:$C,$A7) | E7: =COUNTIFS(data_hits!$A:$A,"moonset",data_hits!$C:$C,$A7) | F7: =COUNTIFS(data_hits!$A:$A,"financialwell",data_hits!$C:$C,$A7) | G7: =COUNTIFS(data_hits!$A:$A,"dddd",data_hits!$C:$C,$A7) | H7: =COUNTIFS(data_hits!$A:$A,"udemy-top-down-shooter",data_hits!$C:$C,$A7) | I7: =SUM(D7:H7) | J7: =K7+L7 | K7: =COUNTIFS(data_adj!$C:$C,$A7,data_adj!$E:$E,"TP") | L7: =COUNTIFS(data_adj!$C:$C,$A7,data_adj!$E:$E,"FP") | M7: =IF(J7=0,"",ROUND(100*K7/J7,1)) | N7: =COUNTIFS(data_llm!$C:$C,$A7) | O7: =COUNTIFS(data_llm!$C:$C,$A7,data_llm!$F:$F,TRUE) | P7: =N7-O7 | Q7: =IF(N7=0,"",ROUND(100*O7/N7,1)) | R7: =IF(J7=0,"",ROUND(I7*K7/J7,0))
A8: arch-12 | B8: Major | C8: Cache Key Lifecycle Mismatch | D8: =COUNTIFS(data_hits!$A:$A,"archon-search",data_hits!$C:$C,$A8) | E8: =COUNTIFS(data_hits!$A:$A,"moonset",data_hits!$C:$C,$A8) | F8: =COUNTIFS(data_hits!$A:$A,"financialwell",data_hits!$C:$C,$A8) | G8: =COUNTIFS(data_hits!$A:$A,"dddd",data_hits!$C:$C,$A8) | H8: =COUNTIFS(data_hits!$A:$A,"udemy-top-down-shooter",data_hits!$C:$C,$A8) | I8: =SUM(D8:H8) | J8: =K8+L8 | K8: =COUNTIFS(data_adj!$C:$C,$A8,data_adj!$E:$E,"TP") | L8: =COUNTIFS(data_adj!$C:$C,$A8,data_adj!$E:$E,"FP") | M8: =IF(J8=0,"",ROUND(100*K8/J8,1)) | N8: =COUNTIFS(data_llm!$C:$C,$A8) | O8: =COUNTIFS(data_llm!$C:$C,$A8,data_llm!$F:$F,TRUE) | P8: =N8-O8 | Q8: =IF(N8=0,"",ROUND(100*O8/N8,1)) | R8: =IF(J8=0,"",ROUND(I8*K8/J8,0))
A9: clarity-06 | B9: Minor | C9: Noise Words in Names | D9: =COUNTIFS(data_hits!$A:$A,"archon-search",data_hits!$C:$C,$A9) | E9: =COUNTIFS(data_hits!$A:$A,"moonset",data_hits!$C:$C,$A9) | F9: =COUNTIFS(data_hits!$A:$A,"financialwell",data_hits!$C:$C,$A9) | G9: =COUNTIFS(data_hits!$A:$A,"dddd",data_hits!$C:$C,$A9) | H9: =COUNTIFS(data_hits!$A:$A,"udemy-top-down-shooter",data_hits!$C:$C,$A9) | I9: =SUM(D9:H9) | J9: =K9+L9 | K9: =COUNTIFS(data_adj!$C:$C,$A9,data_adj!$E:$E,"TP") | L9: =COUNTIFS(data_adj!$C:$C,$A9,data_adj!$E:$E,"FP") | M9: =IF(J9=0,"",ROUND(100*K9/J9,1)) | N9: =COUNTIFS(data_llm!$C:$C,$A9) | O9: =COUNTIFS(data_llm!$C:$C,$A9,data_llm!$F:$F,TRUE) | P9: =N9-O9 | Q9: =IF(N9=0,"",ROUND(100*O9/N9,1)) | R9: =IF(J9=0,"",ROUND(I9*K9/J9,0))
A10: clarity-09 | B10: Moderate | C10: Complex Boolean Conditions Not Extracted | D10: =COUNTIFS(data_hits!$A:$A,"archon-search",data_hits!$C:$C,$A10) | E10: =COUNTIFS(data_hits!$A:$A,"moonset",data_hits!$C:$C,$A10) | F10: =COUNTIFS(data_hits!$A:$A,"financialwell",data_hits!$C:$C,$A10) | G10: =COUNTIFS(data_hits!$A:$A,"dddd",data_hits!$C:$C,$A10) | H10: =COUNTIFS(data_hits!$A:$A,"udemy-top-down-shooter",data_hits!$C:$C,$A10) | I10: =SUM(D10:H10) | J10: =K10+L10 | K10: =COUNTIFS(data_adj!$C:$C,$A10,data_adj!$E:$E,"TP") | L10: =COUNTIFS(data_adj!$C:$C,$A10,data_adj!$E:$E,"FP") | M10: =IF(J10=0,"",ROUND(100*K10/J10,1)) | N10: =COUNTIFS(data_llm!$C:$C,$A10) | O10: =COUNTIFS(data_llm!$C:$C,$A10,data_llm!$F:$F,TRUE) | P10: =N10-O10 | Q10: =IF(N10=0,"",ROUND(100*O10/N10,1)) | R10: =IF(J10=0,"",ROUND(I10*K10/J10,0))
A11: clarity-16 | B11: Major | C11: Cyclomatic Complexity | D11: =COUNTIFS(data_hits!$A:$A,"archon-search",data_hits!$C:$C,$A11) | E11: =COUNTIFS(data_hits!$A:$A,"moonset",data_hits!$C:$C,$A11) | F11: =COUNTIFS(data_hits!$A:$A,"financialwell",data_hits!$C:$C,$A11) | G11: =COUNTIFS(data_hits!$A:$A,"dddd",data_hits!$C:$C,$A11) | H11: =COUNTIFS(data_hits!$A:$A,"udemy-top-down-shooter",data_hits!$C:$C,$A11) | I11: =SUM(D11:H11) | J11: =K11+L11 | K11: =COUNTIFS(data_adj!$C:$C,$A11,data_adj!$E:$E,"TP") | L11: =COUNTIFS(data_adj!$C:$C,$A11,data_adj!$E:$E,"FP") | M11: =IF(J11=0,"",ROUND(100*K11/J11,1)) | N11: =COUNTIFS(data_llm!$C:$C,$A11) | O11: =COUNTIFS(data_llm!$C:$C,$A11,data_llm!$F:$F,TRUE) | P11: =N11-O11 | Q11: =IF(N11=0,"",ROUND(100*O11/N11,1)) | R11: =IF(J11=0,"",ROUND(I11*K11/J11,0))
A12: clarity-17 | B12: Moderate | C12: Function Length | D12: =COUNTIFS(data_hits!$A:$A,"archon-search",data_hits!$C:$C,$A12) | E12: =COUNTIFS(data_hits!$A:$A,"moonset",data_hits!$C:$C,$A12) | F12: =COUNTIFS(data_hits!$A:$A,"financialwell",data_hits!$C:$C,$A12) | G12: =COUNTIFS(data_hits!$A:$A,"dddd",data_hits!$C:$C,$A12) | H12: =COUNTIFS(data_hits!$A:$A,"udemy-top-down-shooter",data_hits!$C:$C,$A12) | I12: =SUM(D12:H12) | J12: =K12+L12 | K12: =COUNTIFS(data_adj!$C:$C,$A12,data_adj!$E:$E,"TP") | L12: =COUNTIFS(data_adj!$C:$C,$A12,data_adj!$E:$E,"FP") | M12: =IF(J12=0,"",ROUND(100*K12/J12,1)) | N12: =COUNTIFS(data_llm!$C:$C,$A12) | O12: =COUNTIFS(data_llm!$C:$C,$A12,data_llm!$F:$F,TRUE) | P12: =N12-O12 | Q12: =IF(N12=0,"",ROUND(100*O12/N12,1)) | R12: =IF(J12=0,"",ROUND(I12*K12/J12,0))
A13: ddd-01 | B13: Major | C13: Value Object Mutability | D13: =COUNTIFS(data_hits!$A:$A,"archon-search",data_hits!$C:$C,$A13) | E13: =COUNTIFS(data_hits!$A:$A,"moonset",data_hits!$C:$C,$A13) | F13: =COUNTIFS(data_hits!$A:$A,"financialwell",data_hits!$C:$C,$A13) | G13: =COUNTIFS(data_hits!$A:$A,"dddd",data_hits!$C:$C,$A13) | H13: =COUNTIFS(data_hits!$A:$A,"udemy-top-down-shooter",data_hits!$C:$C,$A13) | I13: =SUM(D13:H13) | J13: =K13+L13 | K13: =COUNTIFS(data_adj!$C:$C,$A13,data_adj!$E:$E,"TP") | L13: =COUNTIFS(data_adj!$C:$C,$A13,data_adj!$E:$E,"FP") | M13: =IF(J13=0,"",ROUND(100*K13/J13,1)) | N13: =COUNTIFS(data_llm!$C:$C,$A13) | O13: =COUNTIFS(data_llm!$C:$C,$A13,data_llm!$F:$F,TRUE) | P13: =N13-O13 | Q13: =IF(N13=0,"",ROUND(100*O13/N13,1)) | R13: =IF(J13=0,"",ROUND(I13*K13/J13,0))
... A61: tests-13 | B61: Critical | C61: Test Module Containing No Assertions | D61: =COUNTIFS(data_hits!$A:$A,"archon-search",data_hits!$C:$C,$A61) | E61: =COUNTIFS(data_hits!$A:$A,"moonset",data_hits!$C:$C,$A61) | F61: =COUNTIFS(data_hits!$A:$A,"financialwell",data_hits!$C:$C,$A61) | G61: =COUNTIFS(data_hits!$A:$A,"dddd",data_hits!$C:$C,$A61) | H61: =COUNTIFS(data_hits!$A:$A,"udemy-top-down-shooter",data_hits!$C:$C,$A61) | I61: =SUM(D61:H61) | J61: =K61+L61 | K61: =COUNTIFS(data_adj!$C:$C,$A61,data_adj!$E:$E,"TP") | L61: =COUNTIFS(data_adj!$C:$C,$A61,data_adj!$E:$E,"FP") | M61: =IF(J61=0,"",ROUND(100*K61/J61,1)) | N61: =COUNTIFS(data_llm!$C:$C,$A61) | O61: =COUNTIFS(data_llm!$C:$C,$A61,data_llm!$F:$F,TRUE) | P61: =N61-O61 | Q61: =IF(N61=0,"",ROUND(100*O61/N61,1)) | R61: =IF(J61=0,"",ROUND(I61*K61/J61,0))

Sheet archon-search
A1: check | B1: severity | C1: title | D1: hits:archon-search | E1: hits total | F1: adjudicated | G1: TP | H1: FP | I1: precision % | J1: LLM-only found | K1: overlap w/ script | L1: script misses | M1: script coverage % | N1: est. true hits
A2: arch-02 | B2: Major | C2: Use Case Depending on Framework Type | D2: =COUNTIFS(data_hits!$A:$A,"archon-search",data_hits!$C:$C,$A2) | E2: =SUM(D2:D2) | F2: =G2+H2 | G2: =COUNTIFS(data_adj!$A:$A,"archon-search",data_adj!$C:$C,$A2,data_adj!$E:$E,"TP") | H2: =COUNTIFS(data_adj!$A:$A,"archon-search",data_adj!$C:$C,$A2,data_adj!$E:$E,"FP") | I2: =IF(F2=0,"",ROUND(100*G2/F2,1)) | J2: =COUNTIFS(data_llm!$A:$A,"archon-search",data_llm!$C:$C,$A2) | K2: =COUNTIFS(data_llm!$A:$A,"archon-search",data_llm!$C:$C,$A2,data_llm!$F:$F,TRUE) | L2: =J2-K2 | M2: =IF(J2=0,"",ROUND(100*K2/J2,1)) | N2: =IF(F2=0,"",ROUND(E2*G2/F2,0))
A3: arch-03 | B3: Major | C3: Domain Entity with ORM Annotations | D3: =COUNTIFS(data_hits!$A:$A,"archon-search",data_hits!$C:$C,$A3) | E3: =SUM(D3:D3) | F3: =G3+H3 | G3: =COUNTIFS(data_adj!$A:$A,"archon-search",data_adj!$C:$C,$A3,data_adj!$E:$E,"TP") | H3: =COUNTIFS(data_adj!$A:$A,"archon-search",data_adj!$C:$C,$A3,data_adj!$E:$E,"FP") | I3: =IF(F3=0,"",ROUND(100*G3/F3,1)) | J3: =COUNTIFS(data_llm!$A:$A,"archon-search",data_llm!$C:$C,$A3) | K3: =COUNTIFS(data_llm!$A:$A,"archon-search",data_llm!$C:$C,$A3,data_llm!$F:$F,TRUE) | L3: =J3-K3 | M3: =IF(J3=0,"",ROUND(100*K3/J3,1)) | N3: =IF(F3=0,"",ROUND(E3*G3/F3,0))
A4: arch-05 | B4: Major | C4: Infrastructure Exception Leaking | D4: =COUNTIFS(data_hits!$A:$A,"archon-search",data_hits!$C:$C,$A4) | E4: =SUM(D4:D4) | F4: =G4+H4 | G4: =COUNTIFS(data_adj!$A:$A,"archon-search",data_adj!$C:$C,$A4,data_adj!$E:$E,"TP") | H4: =COUNTIFS(data_adj!$A:$A,"archon-search",data_adj!$C:$C,$A4,data_adj!$E:$E,"FP") | I4: =IF(F4=0,"",ROUND(100*G4/F4,1)) | J4: =COUNTIFS(data_llm!$A:$A,"archon-search",data_llm!$C:$C,$A4) | K4: =COUNTIFS(data_llm!$A:$A,"archon-search",data_llm!$C:$C,$A4,data_llm!$F:$F,TRUE) | L4: =J4-K4 | M4: =IF(J4=0,"",ROUND(100*K4/J4,1)) | N4: =IF(F4=0,"",ROUND(E4*G4/F4,0))
A5: arch-08 | B5: Major | C5: Service Locator / Magic Container | D5: =COUNTIFS(data_hits!$A:$A,"archon-search",data_hits!$C:$C,$A5) | E5: =SUM(D5:D5) | F5: =G5+H5 | G5: =COUNTIFS(data_adj!$A:$A,"archon-search",data_adj!$C:$C,$A5,data_adj!$E:$E,"TP") | H5: =COUNTIFS(data_adj!$A:$A,"archon-search",data_adj!$C:$C,$A5,data_adj!$E:$E,"FP") | I5: =IF(F5=0,"",ROUND(100*G5/F5,1)) | J5: =COUNTIFS(data_llm!$A:$A,"archon-search",data_llm!$C:$C,$A5) | K5: =COUNTIFS(data_llm!$A:$A,"archon-search",data_llm!$C:$C,$A5,data_llm!$F:$F,TRUE) | L5: =J5-K5 | M5: =IF(J5=0,"",ROUND(100*K5/J5,1)) | N5: =IF(F5=0,"",ROUND(E5*G5/F5,0))
A6: arch-09 | B6: Moderate | C6: Environment-Specific Branching in Business Logic | D6: =COUNTIFS(data_hits!$A:$A,"archon-search",data_hits!$C:$C,$A6) | E6: =SUM(D6:D6) | F6: =G6+H6 | G6: =COUNTIFS(data_adj!$A:$A,"archon-search",data_adj!$C:$C,$A6,data_adj!$E:$E,"TP") | H6: =COUNTIFS(data_adj!$A:$A,"archon-search",data_adj!$C:$C,$A6,data_adj!$E:$E,"FP") | I6: =IF(F6=0,"",ROUND(100*G6/F6,1)) | J6: =COUNTIFS(data_llm!$A:$A,"archon-search",data_llm!$C:$C,$A6) | K6: =COUNTIFS(data_llm!$A:$A,"archon-search",data_llm!$C:$C,$A6,data_llm!$F:$F,TRUE) | L6: =J6-K6 | M6: =IF(J6=0,"",ROUND(100*K6/J6,1)) | N6: =IF(F6=0,"",ROUND(E6*G6/F6,0))
A7: arch-11 | B7: Moderate | C7: Environment Address Hardcoded in Code | D7: =COUNTIFS(data_hits!$A:$A,"archon-search",data_hits!$C:$C,$A7) | E7: =SUM(D7:D7) | F7: =G7+H7 | G7: =COUNTIFS(data_adj!$A:$A,"archon-search",data_adj!$C:$C,$A7,data_adj!$E:$E,"TP") | H7: =COUNTIFS(data_adj!$A:$A,"archon-search",data_adj!$C:$C,$A7,data_adj!$E:$E,"FP") | I7: =IF(F7=0,"",ROUND(100*G7/F7,1)) | J7: =COUNTIFS(data_llm!$A:$A,"archon-search",data_llm!$C:$C,$A7) | K7: =COUNTIFS(data_llm!$A:$A,"archon-search",data_llm!$C:$C,$A7,data_llm!$F:$F,TRUE) | L7: =J7-K7 | M7: =IF(J7=0,"",ROUND(100*K7/J7,1)) | N7: =IF(F7=0,"",ROUND(E7*G7/F7,0))
A8: arch-12 | B8: Major | C8: Cache Key Lifecycle Mismatch | D8: =COUNTIFS(data_hits!$A:$A,"archon-search",data_hits!$C:$C,$A8) | E8: =SUM(D8:D8) | F8: =G8+H8 | G8: =COUNTIFS(data_adj!$A:$A,"archon-search",data_adj!$C:$C,$A8,data_adj!$E:$E,"TP") | H8: =COUNTIFS(data_adj!$A:$A,"archon-search",data_adj!$C:$C,$A8,data_adj!$E:$E,"FP") | I8: =IF(F8=0,"",ROUND(100*G8/F8,1)) | J8: =COUNTIFS(data_llm!$A:$A,"archon-search",data_llm!$C:$C,$A8) | K8: =COUNTIFS(data_llm!$A:$A,"archon-search",data_llm!$C:$C,$A8,data_llm!$F:$F,TRUE) | L8: =J8-K8 | M8: =IF(J8=0,"",ROUND(100*K8/J8,1)) | N8: =IF(F8=0,"",ROUND(E8*G8/F8,0))
A9: clarity-06 | B9: Minor | C9: Noise Words in Names | D9: =COUNTIFS(data_hits!$A:$A,"archon-search",data_hits!$C:$C,$A9) | E9: =SUM(D9:D9) | F9: =G9+H9 | G9: =COUNTIFS(data_adj!$A:$A,"archon-search",data_adj!$C:$C,$A9,data_adj!$E:$E,"TP") | H9: =COUNTIFS(data_adj!$A:$A,"archon-search",data_adj!$C:$C,$A9,data_adj!$E:$E,"FP") | I9: =IF(F9=0,"",ROUND(100*G9/F9,1)) | J9: =COUNTIFS(data_llm!$A:$A,"archon-search",data_llm!$C:$C,$A9) | K9: =COUNTIFS(data_llm!$A:$A,"archon-search",data_llm!$C:$C,$A9,data_llm!$F:$F,TRUE) | L9: =J9-K9 | M9: =IF(J9=0,"",ROUND(100*K9/J9,1)) | N9: =IF(F9=0,"",ROUND(E9*G9/F9,0))
A10: clarity-09 | B10: Moderate | C10: Complex Boolean Conditions Not Extracted | D10: =COUNTIFS(data_hits!$A:$A,"archon-search",data_hits!$C:$C,$A10) | E10: =SUM(D10:D10) | F10: =G10+H10 | G10: =COUNTIFS(data_adj!$A:$A,"archon-search",data_adj!$C:$C,$A10,data_adj!$E:$E,"TP") | H10: =COUNTIFS(data_adj!$A:$A,"archon-search",data_adj!$C:$C,$A10,data_adj!$E:$E,"FP") | I10: =IF(F10=0,"",ROUND(100*G10/F10,1)) | J10: =COUNTIFS(data_llm!$A:$A,"archon-search",data_llm!$C:$C,$A10) | K10: =COUNTIFS(data_llm!$A:$A,"archon-search",data_llm!$C:$C,$A10,data_llm!$F:$F,TRUE) | L10: =J10-K10 | M10: =IF(J10=0,"",ROUND(100*K10/J10,1)) | N10: =IF(F10=0,"",ROUND(E10*G10/F10,0))
A11: clarity-16 | B11: Major | C11: Cyclomatic Complexity | D11: =COUNTIFS(data_hits!$A:$A,"archon-search",data_hits!$C:$C,$A11) | E11: =SUM(D11:D11) | F11: =G11+H11 | G11: =COUNTIFS(data_adj!$A:$A,"archon-search",data_adj!$C:$C,$A11,data_adj!$E:$E,"TP") | H11: =COUNTIFS(data_adj!$A:$A,"archon-search",data_adj!$C:$C,$A11,data_adj!$E:$E,"FP") | I11: =IF(F11=0,"",ROUND(100*G11/F11,1)) | J11: =COUNTIFS(data_llm!$A:$A,"archon-search",data_llm!$C:$C,$A11) | K11: =COUNTIFS(data_llm!$A:$A,"archon-search",data_llm!$C:$C,$A11,data_llm!$F:$F,TRUE) | L11: =J11-K11 | M11: =IF(J11=0,"",ROUND(100*K11/J11,1)) | N11: =IF(F11=0,"",ROUND(E11*G11/F11,0))
A12: clarity-17 | B12: Moderate | C12: Function Length | D12: =COUNTIFS(data_hits!$A:$A,"archon-search",data_hits!$C:$C,$A12) | E12: =SUM(D12:D12) | F12: =G12+H12 | G12: =COUNTIFS(data_adj!$A:$A,"archon-search",data_adj!$C:$C,$A12,data_adj!$E:$E,"TP") | H12: =COUNTIFS(data_adj!$A:$A,"archon-search",data_adj!$C:$C,$A12,data_adj!$E:$E,"FP") | I12: =IF(F12=0,"",ROUND(100*G12/F12,1)) | J12: =COUNTIFS(data_llm!$A:$A,"archon-search",data_llm!$C:$C,$A12) | K12: =COUNTIFS(data_llm!$A:$A,"archon-search",data_llm!$C:$C,$A12,data_llm!$F:$F,TRUE) | L12: =J12-K12 | M12: =IF(J12=0,"",ROUND(100*K12/J12,1)) | N12: =IF(F12=0,"",ROUND(E12*G12/F12,0))
A13: ddd-01 | B13: Major | C13: Value Object Mutability | D13: =COUNTIFS(data_hits!$A:$A,"archon-search",data_hits!$C:$C,$A13) | E13: =SUM(D13:D13) | F13: =G13+H13 | G13: =COUNTIFS(data_adj!$A:$A,"archon-search",data_adj!$C:$C,$A13,data_adj!$E:$E,"TP") | H13: =COUNTIFS(data_adj!$A:$A,"archon-search",data_adj!$C:$C,$A13,data_adj!$E:$E,"FP") | I13: =IF(F13=0,"",ROUND(100*G13/F13,1)) | J13: =COUNTIFS(data_llm!$A:$A,"archon-search",data_llm!$C:$C,$A13) | K13: =COUNTIFS(data_llm!$A:$A,"archon-search",data_llm!$C:$C,$A13,data_llm!$F:$F,TRUE) | L13: =J13-K13 | M13: =IF(J13=0,"",ROUND(100*K13/J13,1)) | N13: =IF(F13=0,"",ROUND(E13*G13/F13,0))
... A61: tests-13 | B61: Critical | C61: Test Module Containing No Assertions | D61: =COUNTIFS(data_hits!$A:$A,"archon-search",data_hits!$C:$C,$A61) | E61: =SUM(D61:D61) | F61: =G61+H61 | G61: =COUNTIFS(data_adj!$A:$A,"archon-search",data_adj!$C:$C,$A61,data_adj!$E:$E,"TP") | H61: =COUNTIFS(data_adj!$A:$A,"archon-search",data_adj!$C:$C,$A61,data_adj!$E:$E,"FP") | I61: =IF(F61=0,"",ROUND(100*G61/F61,1)) | J61: =COUNTIFS(data_llm!$A:$A,"archon-search",data_llm!$C:$C,$A61) | K61: =COUNTIFS(data_llm!$A:$A,"archon-search",data_llm!$C:$C,$A61,data_llm!$F:$F,TRUE) | L61: =J61-K61 | M61: =IF(J61=0,"",ROUND(100*K61/J61,1)) | N61: =IF(F61=0,"",ROUND(E61*G61/F61,0))

Sheet moonset
A1: check | B1: severity | C1: title | D1: hits:moonset | E1: hits total | F1: adjudicated | G1: TP | H1: FP | I1: precision % | J1: LLM-only found | K1: overlap w/ script | L1: script misses | M1: script coverage % | N1: est. true hits
A2: arch-02 | B2: Major | C2: Use Case Depending on Framework Type | D2: =COUNTIFS(data_hits!$A:$A,"moonset",data_hits!$C:$C,$A2) | E2: =SUM(D2:D2) | F2: =G2+H2 | G2: =COUNTIFS(data_adj!$A:$A,"moonset",data_adj!$C:$C,$A2,data_adj!$E:$E,"TP") | H2: =COUNTIFS(data_adj!$A:$A,"moonset",data_adj!$C:$C,$A2,data_adj!$E:$E,"FP") | I2: =IF(F2=0,"",ROUND(100*G2/F2,1)) | J2: =COUNTIFS(data_llm!$A:$A,"moonset",data_llm!$C:$C,$A2) | K2: =COUNTIFS(data_llm!$A:$A,"moonset",data_llm!$C:$C,$A2,data_llm!$F:$F,TRUE) | L2: =J2-K2 | M2: =IF(J2=0,"",ROUND(100*K2/J2,1)) | N2: =IF(F2=0,"",ROUND(E2*G2/F2,0))
A3: arch-03 | B3: Major | C3: Domain Entity with ORM Annotations | D3: =COUNTIFS(data_hits!$A:$A,"moonset",data_hits!$C:$C,$A3) | E3: =SUM(D3:D3) | F3: =G3+H3 | G3: =COUNTIFS(data_adj!$A:$A,"moonset",data_adj!$C:$C,$A3,data_adj!$E:$E,"TP") | H3: =COUNTIFS(data_adj!$A:$A,"moonset",data_adj!$C:$C,$A3,data_adj!$E:$E,"FP") | I3: =IF(F3=0,"",ROUND(100*G3/F3,1)) | J3: =COUNTIFS(data_llm!$A:$A,"moonset",data_llm!$C:$C,$A3) | K3: =COUNTIFS(data_llm!$A:$A,"moonset",data_llm!$C:$C,$A3,data_llm!$F:$F,TRUE) | L3: =J3-K3 | M3: =IF(J3=0,"",ROUND(100*K3/J3,1)) | N3: =IF(F3=0,"",ROUND(E3*G3/F3,0))
A4: arch-05 | B4: Major | C4: Infrastructure Exception Leaking | D4: =COUNTIFS(data_hits!$A:$A,"moonset",data_hits!$C:$C,$A4) | E4: =SUM(D4:D4) | F4: =G4+H4 | G4: =COUNTIFS(data_adj!$A:$A,"moonset",data_adj!$C:$C,$A4,data_adj!$E:$E,"TP") | H4: =COUNTIFS(data_adj!$A:$A,"moonset",data_adj!$C:$C,$A4,data_adj!$E:$E,"FP") | I4: =IF(F4=0,"",ROUND(100*G4/F4,1)) | J4: =COUNTIFS(data_llm!$A:$A,"moonset",data_llm!$C:$C,$A4) | K4: =COUNTIFS(data_llm!$A:$A,"moonset",data_llm!$C:$C,$A4,data_llm!$F:$F,TRUE) | L4: =J4-K4 | M4: =IF(J4=0,"",ROUND(100*K4/J4,1)) | N4: =IF(F4=0,"",ROUND(E4*G4/F4,0))
A5: arch-08 | B5: Major | C5: Service Locator / Magic Container | D5: =COUNTIFS(data_hits!$A:$A,"moonset",data_hits!$C:$C,$A5) | E5: =SUM(D5:D5) | F5: =G5+H5 | G5: =COUNTIFS(data_adj!$A:$A,"moonset",data_adj!$C:$C,$A5,data_adj!$E:$E,"TP") | H5: =COUNTIFS(data_adj!$A:$A,"moonset",data_adj!$C:$C,$A5,data_adj!$E:$E,"FP") | I5: =IF(F5=0,"",ROUND(100*G5/F5,1)) | J5: =COUNTIFS(data_llm!$A:$A,"moonset",data_llm!$C:$C,$A5) | K5: =COUNTIFS(data_llm!$A:$A,"moonset",data_llm!$C:$C,$A5,data_llm!$F:$F,TRUE) | L5: =J5-K5 | M5: =IF(J5=0,"",ROUND(100*K5/J5,1)) | N5: =IF(F5=0,"",ROUND(E5*G5/F5,0))
A6: arch-09 | B6: Moderate | C6: Environment-Specific Branching in Business Logic | D6: =COUNTIFS(data_hits!$A:$A,"moonset",data_hits!$C:$C,$A6) | E6: =SUM(D6:D6) | F6: =G6+H6 | G6: =COUNTIFS(data_adj!$A:$A,"moonset",data_adj!$C:$C,$A6,data_adj!$E:$E,"TP") | H6: =COUNTIFS(data_adj!$A:$A,"moonset",data_adj!$C:$C,$A6,data_adj!$E:$E,"FP") | I6: =IF(F6=0,"",ROUND(100*G6/F6,1)) | J6: =COUNTIFS(data_llm!$A:$A,"moonset",data_llm!$C:$C,$A6) | K6: =COUNTIFS(data_llm!$A:$A,"moonset",data_llm!$C:$C,$A6,data_llm!$F:$F,TRUE) | L6: =J6-K6 | M6: =IF(J6=0,"",ROUND(100*K6/J6,1)) | N6: =IF(F6=0,"",ROUND(E6*G6/F6,0))
A7: arch-11 | B7: Moderate | C7: Environment Address Hardcoded in Code | D7: =COUNTIFS(data_hits!$A:$A,"moonset",data_hits!$C:$C,$A7) | E7: =SUM(D7:D7) | F7: =G7+H7 | G7: =COUNTIFS(data_adj!$A:$A,"moonset",data_adj!$C:$C,$A7,data_adj!$E:$E,"TP") | H7: =COUNTIFS(data_adj!$A:$A,"moonset",data_adj!$C:$C,$A7,data_adj!$E:$E,"FP") | I7: =IF(F7=0,"",ROUND(100*G7/F7,1)) | J7: =COUNTIFS(data_llm!$A:$A,"moonset",data_llm!$C:$C,$A7) | K7: =COUNTIFS(data_llm!$A:$A,"moonset",data_llm!$C:$C,$A7,data_llm!$F:$F,TRUE) | L7: =J7-K7 | M7: =IF(J7=0,"",ROUND(100*K7/J7,1)) | N7: =IF(F7=0,"",ROUND(E7*G7/F7,0))
A8: arch-12 | B8: Major | C8: Cache Key Lifecycle Mismatch | D8: =COUNTIFS(data_hits!$A:$A,"moonset",data_hits!$C:$C,$A8) | E8: =SUM(D8:D8) | F8: =G8+H8 | G8: =COUNTIFS(data_adj!$A:$A,"moonset",data_adj!$C:$C,$A8,data_adj!$E:$E,"TP") | H8: =COUNTIFS(data_adj!$A:$A,"moonset",data_adj!$C:$C,$A8,data_adj!$E:$E,"FP") | I8: =IF(F8=0,"",ROUND(100*G8/F8,1)) | J8: =COUNTIFS(data_llm!$A:$A,"moonset",data_llm!$C:$C,$A8) | K8: =COUNTIFS(data_llm!$A:$A,"moonset",data_llm!$C:$C,$A8,data_llm!$F:$F,TRUE) | L8: =J8-K8 | M8: =IF(J8=0,"",ROUND(100*K8/J8,1)) | N8: =IF(F8=0,"",ROUND(E8*G8/F8,0))
A9: clarity-06 | B9: Minor | C9: Noise Words in Names | D9: =COUNTIFS(data_hits!$A:$A,"moonset",data_hits!$C:$C,$A9) | E9: =SUM(D9:D9) | F9: =G9+H9 | G9: =COUNTIFS(data_adj!$A:$A,"moonset",data_adj!$C:$C,$A9,data_adj!$E:$E,"TP") | H9: =COUNTIFS(data_adj!$A:$A,"moonset",data_adj!$C:$C,$A9,data_adj!$E:$E,"FP") | I9: =IF(F9=0,"",ROUND(100*G9/F9,1)) | J9: =COUNTIFS(data_llm!$A:$A,"moonset",data_llm!$C:$C,$A9) | K9: =COUNTIFS(data_llm!$A:$A,"moonset",data_llm!$C:$C,$A9,data_llm!$F:$F,TRUE) | L9: =J9-K9 | M9: =IF(J9=0,"",ROUND(100*K9/J9,1)) | N9: =IF(F9=0,"",ROUND(E9*G9/F9,0))
A10: clarity-09 | B10: Moderate | C10: Complex Boolean Conditions Not Extracted | D10: =COUNTIFS(data_hits!$A:$A,"moonset",data_hits!$C:$C,$A10) | E10: =SUM(D10:D10) | F10: =G10+H10 | G10: =COUNTIFS(data_adj!$A:$A,"moonset",data_adj!$C:$C,$A10,data_adj!$E:$E,"TP") | H10: =COUNTIFS(data_adj!$A:$A,"moonset",data_adj!$C:$C,$A10,data_adj!$E:$E,"FP") | I10: =IF(F10=0,"",ROUND(100*G10/F10,1)) | J10: =COUNTIFS(data_llm!$A:$A,"moonset",data_llm!$C:$C,$A10) | K10: =COUNTIFS(data_llm!$A:$A,"moonset",data_llm!$C:$C,$A10,data_llm!$F:$F,TRUE) | L10: =J10-K10 | M10: =IF(J10=0,"",ROUND(100*K10/J10,1)) | N10: =IF(F10=0,"",ROUND(E10*G10/F10,0))
A11: clarity-16 | B11: Major | C11: Cyclomatic Complexity | D11: =COUNTIFS(data_hits!$A:$A,"moonset",data_hits!$C:$C,$A11) | E11: =SUM(D11:D11) | F11: =G11+H11 | G11: =COUNTIFS(data_adj!$A:$A,"moonset",data_adj!$C:$C,$A11,data_adj!$E:$E,"TP") | H11: =COUNTIFS(data_adj!$A:$A,"moonset",data_adj!$C:$C,$A11,data_adj!$E:$E,"FP") | I11: =IF(F11=0,"",ROUND(100*G11/F11,1)) | J11: =COUNTIFS(data_llm!$A:$A,"moonset",data_llm!$C:$C,$A11) | K11: =COUNTIFS(data_llm!$A:$A,"moonset",data_llm!$C:$C,$A11,data_llm!$F:$F,TRUE) | L11: =J11-K11 | M11: =IF(J11=0,"",ROUND(100*K11/J11,1)) | N11: =IF(F11=0,"",ROUND(E11*G11/F11,0))
A12: clarity-17 | B12: Moderate | C12: Function Length | D12: =COUNTIFS(data_hits!$A:$A,"moonset",data_hits!$C:$C,$A12) | E12: =SUM(D12:D12) | F12: =G12+H12 | G12: =COUNTIFS(data_adj!$A:$A,"moonset",data_adj!$C:$C,$A12,data_adj!$E:$E,"TP") | H12: =COUNTIFS(data_adj!$A:$A,"moonset",data_adj!$C:$C,$A12,data_adj!$E:$E,"FP") | I12: =IF(F12=0,"",ROUND(100*G12/F12,1)) | J12: =COUNTIFS(data_llm!$A:$A,"moonset",data_llm!$C:$C,$A12) | K12: =COUNTIFS(data_llm!$A:$A,"moonset",data_llm!$C:$C,$A12,data_llm!$F:$F,TRUE) | L12: =J12-K12 | M12: =IF(J12=0,"",ROUND(100*K12/J12,1)) | N12: =IF(F12=0,"",ROUND(E12*G12/F12,0))
A13: ddd-01 | B13: Major | C13: Value Object Mutability | D13: =COUNTIFS(data_hits!$A:$A,"moonset",data_hits!$C:$C,$A13) | E13: =SUM(D13:D13) | F13: =G13+H13 | G13: =COUNTIFS(data_adj!$A:$A,"moonset",data_adj!$C:$C,$A13,data_adj!$E:$E,"TP") | H13: =COUNTIFS(data_adj!$A:$A,"moonset",data_adj!$C:$C,$A13,data_adj!$E:$E,"FP") | I13: =IF(F13=0,"",ROUND(100*G13/F13,1)) | J13: =COUNTIFS(data_llm!$A:$A,"moonset",data_llm!$C:$C,$A13) | K13: =COUNTIFS(data_llm!$A:$A,"moonset",data_llm!$C:$C,$A13,data_llm!$F:$F,TRUE) | L13: =J13-K13 | M13: =IF(J13=0,"",ROUND(100*K13/J13,1)) | N13: =IF(F13=0,"",ROUND(E13*G13/F13,0))
... A61: tests-13 | B61: Critical | C61: Test Module Containing No Assertions | D61: =COUNTIFS(data_hits!$A:$A,"moonset",data_hits!$C:$C,$A61) | E61: =SUM(D61:D61) | F61: =G61+H61 | G61: =COUNTIFS(data_adj!$A:$A,"moonset",data_adj!$C:$C,$A61,data_adj!$E:$E,"TP") | H61: =COUNTIFS(data_adj!$A:$A,"moonset",data_adj!$C:$C,$A61,data_adj!$E:$E,"FP") | I61: =IF(F61=0,"",ROUND(100*G61/F61,1)) | J61: =COUNTIFS(data_llm!$A:$A,"moonset",data_llm!$C:$C,$A61) | K61: =COUNTIFS(data_llm!$A:$A,"moonset",data_llm!$C:$C,$A61,data_llm!$F:$F,TRUE) | L61: =J61-K61 | M61: =IF(J61=0,"",ROUND(100*K61/J61,1)) | N61: =IF(F61=0,"",ROUND(E61*G61/F61,0))

Sheet financialwell
A1: check | B1: severity | C1: title | D1: hits:financialwell | E1: hits total | F1: adjudicated | G1: TP | H1: FP | I1: precision % | J1: LLM-only found | K1: overlap w/ script | L1: script misses | M1: script coverage % | N1: est. true hits
A2: arch-02 | B2: Major | C2: Use Case Depending on Framework Type | D2: =COUNTIFS(data_hits!$A:$A,"financialwell",data_hits!$C:$C,$A2) | E2: =SUM(D2:D2) | F2: =G2+H2 | G2: =COUNTIFS(data_adj!$A:$A,"financialwell",data_adj!$C:$C,$A2,data_adj!$E:$E,"TP") | H2: =COUNTIFS(data_adj!$A:$A,"financialwell",data_adj!$C:$C,$A2,data_adj!$E:$E,"FP") | I2: =IF(F2=0,"",ROUND(100*G2/F2,1)) | J2: =COUNTIFS(data_llm!$A:$A,"financialwell",data_llm!$C:$C,$A2) | K2: =COUNTIFS(data_llm!$A:$A,"financialwell",data_llm!$C:$C,$A2,data_llm!$F:$F,TRUE) | L2: =J2-K2 | M2: =IF(J2=0,"",ROUND(100*K2/J2,1)) | N2: =IF(F2=0,"",ROUND(E2*G2/F2,0))
A3: arch-03 | B3: Major | C3: Domain Entity with ORM Annotations | D3: =COUNTIFS(data_hits!$A:$A,"financialwell",data_hits!$C:$C,$A3) | E3: =SUM(D3:D3) | F3: =G3+H3 | G3: =COUNTIFS(data_adj!$A:$A,"financialwell",data_adj!$C:$C,$A3,data_adj!$E:$E,"TP") | H3: =COUNTIFS(data_adj!$A:$A,"financialwell",data_adj!$C:$C,$A3,data_adj!$E:$E,"FP") | I3: =IF(F3=0,"",ROUND(100*G3/F3,1)) | J3: =COUNTIFS(data_llm!$A:$A,"financialwell",data_llm!$C:$C,$A3) | K3: =COUNTIFS(data_llm!$A:$A,"financialwell",data_llm!$C:$C,$A3,data_llm!$F:$F,TRUE) | L3: =J3-K3 | M3: =IF(J3=0,"",ROUND(100*K3/J3,1)) | N3: =IF(F3=0,"",ROUND(E3*G3/F3,0))
A4: arch-05 | B4: Major | C4: Infrastructure Exception Leaking | D4: =COUNTIFS(data_hits!$A:$A,"financialwell",data_hits!$C:$C,$A4) | E4: =SUM(D4:D4) | F4: =G4+H4 | G4: =COUNTIFS(data_adj!$A:$A,"financialwell",data_adj!$C:$C,$A4,data_adj!$E:$E,"TP") | H4: =COUNTIFS(data_adj!$A:$A,"financialwell",data_adj!$C:$C,$A4,data_adj!$E:$E,"FP") | I4: =IF(F4=0,"",ROUND(100*G4/F4,1)) | J4: =COUNTIFS(data_llm!$A:$A,"financialwell",data_llm!$C:$C,$A4) | K4: =COUNTIFS(data_llm!$A:$A,"financialwell",data_llm!$C:$C,$A4,data_llm!$F:$F,TRUE) | L4: =J4-K4 | M4: =IF(J4=0,"",ROUND(100*K4/J4,1)) | N4: =IF(F4=0,"",ROUND(E4*G4/F4,0))
A5: arch-08 | B5: Major | C5: Service Locator / Magic Container | D5: =COUNTIFS(data_hits!$A:$A,"financialwell",data_hits!$C:$C,$A5) | E5: =SUM(D5:D5) | F5: =G5+H5 | G5: =COUNTIFS(data_adj!$A:$A,"financialwell",data_adj!$C:$C,$A5,data_adj!$E:$E,"TP") | H5: =COUNTIFS(data_adj!$A:$A,"financialwell",data_adj!$C:$C,$A5,data_adj!$E:$E,"FP") | I5: =IF(F5=0,"",ROUND(100*G5/F5,1)) | J5: =COUNTIFS(data_llm!$A:$A,"financialwell",data_llm!$C:$C,$A5) | K5: =COUNTIFS(data_llm!$A:$A,"financialwell",data_llm!$C:$C,$A5,data_llm!$F:$F,TRUE) | L5: =J5-K5 | M5: =IF(J5=0,"",ROUND(100*K5/J5,1)) | N5: =IF(F5=0,"",ROUND(E5*G5/F5,0))
A6: arch-09 | B6: Moderate | C6: Environment-Specific Branching in Business Logic | D6: =COUNTIFS(data_hits!$A:$A,"financialwell",data_hits!$C:$C,$A6) | E6: =SUM(D6:D6) | F6: =G6+H6 | G6: =COUNTIFS(data_adj!$A:$A,"financialwell",data_adj!$C:$C,$A6,data_adj!$E:$E,"TP") | H6: =COUNTIFS(data_adj!$A:$A,"financialwell",data_adj!$C:$C,$A6,data_adj!$E:$E,"FP") | I6: =IF(F6=0,"",ROUND(100*G6/F6,1)) | J6: =COUNTIFS(data_llm!$A:$A,"financialwell",data_llm!$C:$C,$A6) | K6: =COUNTIFS(data_llm!$A:$A,"financialwell",data_llm!$C:$C,$A6,data_llm!$F:$F,TRUE) | L6: =J6-K6 | M6: =IF(J6=0,"",ROUND(100*K6/J6,1)) | N6: =IF(F6=0,"",ROUND(E6*G6/F6,0))
A7: arch-11 | B7: Moderate | C7: Environment Address Hardcoded in Code | D7: =COUNTIFS(data_hits!$A:$A,"financialwell",data_hits!$C:$C,$A7) | E7: =SUM(D7:D7) | F7: =G7+H7 | G7: =COUNTIFS(data_adj!$A:$A,"financialwell",data_adj!$C:$C,$A7,data_adj!$E:$E,"TP") | H7: =COUNTIFS(data_adj!$A:$A,"financialwell",data_adj!$C:$C,$A7,data_adj!$E:$E,"FP") | I7: =IF(F7=0,"",ROUND(100*G7/F7,1)) | J7: =COUNTIFS(data_llm!$A:$A,"financialwell",data_llm!$C:$C,$A7) | K7: =COUNTIFS(data_llm!$A:$A,"financialwell",data_llm!$C:$C,$A7,data_llm!$F:$F,TRUE) | L7: =J7-K7 | M7: =IF(J7=0,"",ROUND(100*K7/J7,1)) | N7: =IF(F7=0,"",ROUND(E7*G7/F7,0))
A8: arch-12 | B8: Major | C8: Cache Key Lifecycle Mismatch | D8: =COUNTIFS(data_hits!$A:$A,"financialwell",data_hits!$C:$C,$A8) | E8: =SUM(D8:D8) | F8: =G8+H8 | G8: =COUNTIFS(data_adj!$A:$A,"financialwell",data_adj!$C:$C,$A8,data_adj!$E:$E,"TP") | H8: =COUNTIFS(data_adj!$A:$A,"financialwell",data_adj!$C:$C,$A8,data_adj!$E:$E,"FP") | I8: =IF(F8=0,"",ROUND(100*G8/F8,1)) | J8: =COUNTIFS(data_llm!$A:$A,"financialwell",data_llm!$C:$C,$A8) | K8: =COUNTIFS(data_llm!$A:$A,"financialwell",data_llm!$C:$C,$A8,data_llm!$F:$F,TRUE) | L8: =J8-K8 | M8: =IF(J8=0,"",ROUND(100*K8/J8,1)) | N8: =IF(F8=0,"",ROUND(E8*G8/F8,0))
A9: clarity-06 | B9: Minor | C9: Noise Words in Names | D9: =COUNTIFS(data_hits!$A:$A,"financialwell",data_hits!$C:$C,$A9) | E9: =SUM(D9:D9) | F9: =G9+H9 | G9: =COUNTIFS(data_adj!$A:$A,"financialwell",data_adj!$C:$C,$A9,data_adj!$E:$E,"TP") | H9: =COUNTIFS(data_adj!$A:$A,"financialwell",data_adj!$C:$C,$A9,data_adj!$E:$E,"FP") | I9: =IF(F9=0,"",ROUND(100*G9/F9,1)) | J9: =COUNTIFS(data_llm!$A:$A,"financialwell",data_llm!$C:$C,$A9) | K9: =COUNTIFS(data_llm!$A:$A,"financialwell",data_llm!$C:$C,$A9,data_llm!$F:$F,TRUE) | L9: =J9-K9 | M9: =IF(J9=0,"",ROUND(100*K9/J9,1)) | N9: =IF(F9=0,"",ROUND(E9*G9/F9,0))
A10: clarity-09 | B10: Moderate | C10: Complex Boolean Conditions Not Extracted | D10: =COUNTIFS(data_hits!$A:$A,"financialwell",data_hits!$C:$C,$A10) | E10: =SUM(D10:D10) | F10: =G10+H10 | G10: =COUNTIFS(data_adj!$A:$A,"financialwell",data_adj!$C:$C,$A10,data_adj!$E:$E,"TP") | H10: =COUNTIFS(data_adj!$A:$A,"financialwell",data_adj!$C:$C,$A10,data_adj!$E:$E,"FP") | I10: =IF(F10=0,"",ROUND(100*G10/F10,1)) | J10: =COUNTIFS(data_llm!$A:$A,"financialwell",data_llm!$C:$C,$A10) | K10: =COUNTIFS(data_llm!$A:$A,"financialwell",data_llm!$C:$C,$A10,data_llm!$F:$F,TRUE) | L10: =J10-K10 | M10: =IF(J10=0,"",ROUND(100*K10/J10,1)) | N10: =IF(F10=0,"",ROUND(E10*G10/F10,0))
A11: clarity-16 | B11: Major | C11: Cyclomatic Complexity | D11: =COUNTIFS(data_hits!$A:$A,"financialwell",data_hits!$C:$C,$A11) | E11: =SUM(D11:D11) | F11: =G11+H11 | G11: =COUNTIFS(data_adj!$A:$A,"financialwell",data_adj!$C:$C,$A11,data_adj!$E:$E,"TP") | H11: =COUNTIFS(data_adj!$A:$A,"financialwell",data_adj!$C:$C,$A11,data_adj!$E:$E,"FP") | I11: =IF(F11=0,"",ROUND(100*G11/F11,1)) | J11: =COUNTIFS(data_llm!$A:$A,"financialwell",data_llm!$C:$C,$A11) | K11: =COUNTIFS(data_llm!$A:$A,"financialwell",data_llm!$C:$C,$A11,data_llm!$F:$F,TRUE) | L11: =J11-K11 | M11: =IF(J11=0,"",ROUND(100*K11/J11,1)) | N11: =IF(F11=0,"",ROUND(E11*G11/F11,0))
A12: clarity-17 | B12: Moderate | C12: Function Length | D12: =COUNTIFS(data_hits!$A:$A,"financialwell",data_hits!$C:$C,$A12) | E12: =SUM(D12:D12) | F12: =G12+H12 | G12: =COUNTIFS(data_adj!$A:$A,"financialwell",data_adj!$C:$C,$A12,data_adj!$E:$E,"TP") | H12: =COUNTIFS(data_adj!$A:$A,"financialwell",data_adj!$C:$C,$A12,data_adj!$E:$E,"FP") | I12: =IF(F12=0,"",ROUND(100*G12/F12,1)) | J12: =COUNTIFS(data_llm!$A:$A,"financialwell",data_llm!$C:$C,$A12) | K12: =COUNTIFS(data_llm!$A:$A,"financialwell",data_llm!$C:$C,$A12,data_llm!$F:$F,TRUE) | L12: =J12-K12 | M12: =IF(J12=0,"",ROUND(100*K12/J12,1)) | N12: =IF(F12=0,"",ROUND(E12*G12/F12,0))
A13: ddd-01 | B13: Major | C13: Value Object Mutability | D13: =COUNTIFS(data_hits!$A:$A,"financialwell",data_hits!$C:$C,$A13) | E13: =SUM(D13:D13) | F13: =G13+H13 | G13: =COUNTIFS(data_adj!$A:$A,"financialwell",data_adj!$C:$C,$A13,data_adj!$E:$E,"TP") | H13: =COUNTIFS(data_adj!$A:$A,"financialwell",data_adj!$C:$C,$A13,data_adj!$E:$E,"FP") | I13: =IF(F13=0,"",ROUND(100*G13/F13,1)) | J13: =COUNTIFS(data_llm!$A:$A,"financialwell",data_llm!$C:$C,$A13) | K13: =COUNTIFS(data_llm!$A:$A,"financialwell",data_llm!$C:$C,$A13,data_llm!$F:$F,TRUE) | L13: =J13-K13 | M13: =IF(J13=0,"",ROUND(100*K13/J13,1)) | N13: =IF(F13=0,"",ROUND(E13*G13/F13,0))
... A61: tests-13 | B61: Critical | C61: Test Module Containing No Assertions | D61: =COUNTIFS(data_hits!$A:$A,"financialwell",data_hits!$C:$C,$A61) | E61: =SUM(D61:D61) | F61: =G61+H61 | G61: =COUNTIFS(data_adj!$A:$A,"financialwell",data_adj!$C:$C,$A61,data_adj!$E:$E,"TP") | H61: =COUNTIFS(data_adj!$A:$A,"financialwell",data_adj!$C:$C,$A61,data_adj!$E:$E,"FP") | I61: =IF(F61=0,"",ROUND(100*G61/F61,1)) | J61: =COUNTIFS(data_llm!$A:$A,"financialwell",data_llm!$C:$C,$A61) | K61: =COUNTIFS(data_llm!$A:$A,"financialwell",data_llm!$C:$C,$A61,data_llm!$F:$F,TRUE) | L61: =J61-K61 | M61: =IF(J61=0,"",ROUND(100*K61/J61,1)) | N61: =IF(F61=0,"",ROUND(E61*G61/F61,0))

Sheet dddd
A1: check | B1: severity | C1: title | D1: hits:dddd | E1: hits total | F1: adjudicated | G1: TP | H1: FP | I1: precision % | J1: LLM-only found | K1: overlap w/ script | L1: script misses | M1: script coverage % | N1: est. true hits
A2: arch-02 | B2: Major | C2: Use Case Depending on Framework Type | D2: =COUNTIFS(data_hits!$A:$A,"dddd",data_hits!$C:$C,$A2) | E2: =SUM(D2:D2) | F2: =G2+H2 | G2: =COUNTIFS(data_adj!$A:$A,"dddd",data_adj!$C:$C,$A2,data_adj!$E:$E,"TP") | H2: =COUNTIFS(data_adj!$A:$A,"dddd",data_adj!$C:$C,$A2,data_adj!$E:$E,"FP") | I2: =IF(F2=0,"",ROUND(100*G2/F2,1)) | J2: =COUNTIFS(data_llm!$A:$A,"dddd",data_llm!$C:$C,$A2) | K2: =COUNTIFS(data_llm!$A:$A,"dddd",data_llm!$C:$C,$A2,data_llm!$F:$F,TRUE) | L2: =J2-K2 | M2: =IF(J2=0,"",ROUND(100*K2/J2,1)) | N2: =IF(F2=0,"",ROUND(E2*G2/F2,0))
A3: arch-03 | B3: Major | C3: Domain Entity with ORM Annotations | D3: =COUNTIFS(data_hits!$A:$A,"dddd",data_hits!$C:$C,$A3) | E3: =SUM(D3:D3) | F3: =G3+H3 | G3: =COUNTIFS(data_adj!$A:$A,"dddd",data_adj!$C:$C,$A3,data_adj!$E:$E,"TP") | H3: =COUNTIFS(data_adj!$A:$A,"dddd",data_adj!$C:$C,$A3,data_adj!$E:$E,"FP") | I3: =IF(F3=0,"",ROUND(100*G3/F3,1)) | J3: =COUNTIFS(data_llm!$A:$A,"dddd",data_llm!$C:$C,$A3) | K3: =COUNTIFS(data_llm!$A:$A,"dddd",data_llm!$C:$C,$A3,data_llm!$F:$F,TRUE) | L3: =J3-K3 | M3: =IF(J3=0,"",ROUND(100*K3/J3,1)) | N3: =IF(F3=0,"",ROUND(E3*G3/F3,0))
A4: arch-05 | B4: Major | C4: Infrastructure Exception Leaking | D4: =COUNTIFS(data_hits!$A:$A,"dddd",data_hits!$C:$C,$A4) | E4: =SUM(D4:D4) | F4: =G4+H4 | G4: =COUNTIFS(data_adj!$A:$A,"dddd",data_adj!$C:$C,$A4,data_adj!$E:$E,"TP") | H4: =COUNTIFS(data_adj!$A:$A,"dddd",data_adj!$C:$C,$A4,data_adj!$E:$E,"FP") | I4: =IF(F4=0,"",ROUND(100*G4/F4,1)) | J4: =COUNTIFS(data_llm!$A:$A,"dddd",data_llm!$C:$C,$A4) | K4: =COUNTIFS(data_llm!$A:$A,"dddd",data_llm!$C:$C,$A4,data_llm!$F:$F,TRUE) | L4: =J4-K4 | M4: =IF(J4=0,"",ROUND(100*K4/J4,1)) | N4: =IF(F4=0,"",ROUND(E4*G4/F4,0))
A5: arch-08 | B5: Major | C5: Service Locator / Magic Container | D5: =COUNTIFS(data_hits!$A:$A,"dddd",data_hits!$C:$C,$A5) | E5: =SUM(D5:D5) | F5: =G5+H5 | G5: =COUNTIFS(data_adj!$A:$A,"dddd",data_adj!$C:$C,$A5,data_adj!$E:$E,"TP") | H5: =COUNTIFS(data_adj!$A:$A,"dddd",data_adj!$C:$C,$A5,data_adj!$E:$E,"FP") | I5: =IF(F5=0,"",ROUND(100*G5/F5,1)) | J5: =COUNTIFS(data_llm!$A:$A,"dddd",data_llm!$C:$C,$A5) | K5: =COUNTIFS(data_llm!$A:$A,"dddd",data_llm!$C:$C,$A5,data_llm!$F:$F,TRUE) | L5: =J5-K5 | M5: =IF(J5=0,"",ROUND(100*K5/J5,1)) | N5: =IF(F5=0,"",ROUND(E5*G5/F5,0))
A6: arch-09 | B6: Moderate | C6: Environment-Specific Branching in Business Logic | D6: =COUNTIFS(data_hits!$A:$A,"dddd",data_hits!$C:$C,$A6) | E6: =SUM(D6:D6) | F6: =G6+H6 | G6: =COUNTIFS(data_adj!$A:$A,"dddd",data_adj!$C:$C,$A6,data_adj!$E:$E,"TP") | H6: =COUNTIFS(data_adj!$A:$A,"dddd",data_adj!$C:$C,$A6,data_adj!$E:$E,"FP") | I6: =IF(F6=0,"",ROUND(100*G6/F6,1)) | J6: =COUNTIFS(data_llm!$A:$A,"dddd",data_llm!$C:$C,$A6) | K6: =COUNTIFS(data_llm!$A:$A,"dddd",data_llm!$C:$C,$A6,data_llm!$F:$F,TRUE) | L6: =J6-K6 | M6: =IF(J6=0,"",ROUND(100*K6/J6,1)) | N6: =IF(F6=0,"",ROUND(E6*G6/F6,0))
A7: arch-11 | B7: Moderate | C7: Environment Address Hardcoded in Code | D7: =COUNTIFS(data_hits!$A:$A,"dddd",data_hits!$C:$C,$A7) | E7: =SUM(D7:D7) | F7: =G7+H7 | G7: =COUNTIFS(data_adj!$A:$A,"dddd",data_adj!$C:$C,$A7,data_adj!$E:$E,"TP") | H7: =COUNTIFS(data_adj!$A:$A,"dddd",data_adj!$C:$C,$A7,data_adj!$E:$E,"FP") | I7: =IF(F7=0,"",ROUND(100*G7/F7,1)) | J7: =COUNTIFS(data_llm!$A:$A,"dddd",data_llm!$C:$C,$A7) | K7: =COUNTIFS(data_llm!$A:$A,"dddd",data_llm!$C:$C,$A7,data_llm!$F:$F,TRUE) | L7: =J7-K7 | M7: =IF(J7=0,"",ROUND(100*K7/J7,1)) | N7: =IF(F7=0,"",ROUND(E7*G7/F7,0))
A8: arch-12 | B8: Major | C8: Cache Key Lifecycle Mismatch | D8: =COUNTIFS(data_hits!$A:$A,"dddd",data_hits!$C:$C,$A8) | E8: =SUM(D8:D8) | F8: =G8+H8 | G8: =COUNTIFS(data_adj!$A:$A,"dddd",data_adj!$C:$C,$A8,data_adj!$E:$E,"TP") | H8: =COUNTIFS(data_adj!$A:$A,"dddd",data_adj!$C:$C,$A8,data_adj!$E:$E,"FP") | I8: =IF(F8=0,"",ROUND(100*G8/F8,1)) | J8: =COUNTIFS(data_llm!$A:$A,"dddd",data_llm!$C:$C,$A8) | K8: =COUNTIFS(data_llm!$A:$A,"dddd",data_llm!$C:$C,$A8,data_llm!$F:$F,TRUE) | L8: =J8-K8 | M8: =IF(J8=0,"",ROUND(100*K8/J8,1)) | N8: =IF(F8=0,"",ROUND(E8*G8/F8,0))
A9: clarity-06 | B9: Minor | C9: Noise Words in Names | D9: =COUNTIFS(data_hits!$A:$A,"dddd",data_hits!$C:$C,$A9) | E9: =SUM(D9:D9) | F9: =G9+H9 | G9: =COUNTIFS(data_adj!$A:$A,"dddd",data_adj!$C:$C,$A9,data_adj!$E:$E,"TP") | H9: =COUNTIFS(data_adj!$A:$A,"dddd",data_adj!$C:$C,$A9,data_adj!$E:$E,"FP") | I9: =IF(F9=0,"",ROUND(100*G9/F9,1)) | J9: =COUNTIFS(data_llm!$A:$A,"dddd",data_llm!$C:$C,$A9) | K9: =COUNTIFS(data_llm!$A:$A,"dddd",data_llm!$C:$C,$A9,data_llm!$F:$F,TRUE) | L9: =J9-K9 | M9: =IF(J9=0,"",ROUND(100*K9/J9,1)) | N9: =IF(F9=0,"",ROUND(E9*G9/F9,0))
A10: clarity-09 | B10: Moderate | C10: Complex Boolean Conditions Not Extracted | D10: =COUNTIFS(data_hits!$A:$A,"dddd",data_hits!$C:$C,$A10) | E10: =SUM(D10:D10) | F10: =G10+H10 | G10: =COUNTIFS(data_adj!$A:$A,"dddd",data_adj!$C:$C,$A10,data_adj!$E:$E,"TP") | H10: =COUNTIFS(data_adj!$A:$A,"dddd",data_adj!$C:$C,$A10,data_adj!$E:$E,"FP") | I10: =IF(F10=0,"",ROUND(100*G10/F10,1)) | J10: =COUNTIFS(data_llm!$A:$A,"dddd",data_llm!$C:$C,$A10) | K10: =COUNTIFS(data_llm!$A:$A,"dddd",data_llm!$C:$C,$A10,data_llm!$F:$F,TRUE) | L10: =J10-K10 | M10: =IF(J10=0,"",ROUND(100*K10/J10,1)) | N10: =IF(F10=0,"",ROUND(E10*G10/F10,0))
A11: clarity-16 | B11: Major | C11: Cyclomatic Complexity | D11: =COUNTIFS(data_hits!$A:$A,"dddd",data_hits!$C:$C,$A11) | E11: =SUM(D11:D11) | F11: =G11+H11 | G11: =COUNTIFS(data_adj!$A:$A,"dddd",data_adj!$C:$C,$A11,data_adj!$E:$E,"TP") | H11: =COUNTIFS(data_adj!$A:$A,"dddd",data_adj!$C:$C,$A11,data_adj!$E:$E,"FP") | I11: =IF(F11=0,"",ROUND(100*G11/F11,1)) | J11: =COUNTIFS(data_llm!$A:$A,"dddd",data_llm!$C:$C,$A11) | K11: =COUNTIFS(data_llm!$A:$A,"dddd",data_llm!$C:$C,$A11,data_llm!$F:$F,TRUE) | L11: =J11-K11 | M11: =IF(J11=0,"",ROUND(100*K11/J11,1)) | N11: =IF(F11=0,"",ROUND(E11*G11/F11,0))
A12: clarity-17 | B12: Moderate | C12: Function Length | D12: =COUNTIFS(data_hits!$A:$A,"dddd",data_hits!$C:$C,$A12) | E12: =SUM(D12:D12) | F12: =G12+H12 | G12: =COUNTIFS(data_adj!$A:$A,"dddd",data_adj!$C:$C,$A12,data_adj!$E:$E,"TP") | H12: =COUNTIFS(data_adj!$A:$A,"dddd",data_adj!$C:$C,$A12,data_adj!$E:$E,"FP") | I12: =IF(F12=0,"",ROUND(100*G12/F12,1)) | J12: =COUNTIFS(data_llm!$A:$A,"dddd",data_llm!$C:$C,$A12) | K12: =COUNTIFS(data_llm!$A:$A,"dddd",data_llm!$C:$C,$A12,data_llm!$F:$F,TRUE) | L12: =J12-K12 | M12: =IF(J12=0,"",ROUND(100*K12/J12,1)) | N12: =IF(F12=0,"",ROUND(E12*G12/F12,0))
A13: ddd-01 | B13: Major | C13: Value Object Mutability | D13: =COUNTIFS(data_hits!$A:$A,"dddd",data_hits!$C:$C,$A13) | E13: =SUM(D13:D13) | F13: =G13+H13 | G13: =COUNTIFS(data_adj!$A:$A,"dddd",data_adj!$C:$C,$A13,data_adj!$E:$E,"TP") | H13: =COUNTIFS(data_adj!$A:$A,"dddd",data_adj!$C:$C,$A13,data_adj!$E:$E,"FP") | I13: =IF(F13=0,"",ROUND(100*G13/F13,1)) | J13: =COUNTIFS(data_llm!$A:$A,"dddd",data_llm!$C:$C,$A13) | K13: =COUNTIFS(data_llm!$A:$A,"dddd",data_llm!$C:$C,$A13,data_llm!$F:$F,TRUE) | L13: =J13-K13 | M13: =IF(J13=0,"",ROUND(100*K13/J13,1)) | N13: =IF(F13=0,"",ROUND(E13*G13/F13,0))
... A61: tests-13 | B61: Critical | C61: Test Module Containing No Assertions | D61: =COUNTIFS(data_hits!$A:$A,"dddd",data_hits!$C:$C,$A61) | E61: =SUM(D61:D61) | F61: =G61+H61 | G61: =COUNTIFS(data_adj!$A:$A,"dddd",data_adj!$C:$C,$A61,data_adj!$E:$E,"TP") | H61: =COUNTIFS(data_adj!$A:$A,"dddd",data_adj!$C:$C,$A61,data_adj!$E:$E,"FP") | I61: =IF(F61=0,"",ROUND(100*G61/F61,1)) | J61: =COUNTIFS(data_llm!$A:$A,"dddd",data_llm!$C:$C,$A61) | K61: =COUNTIFS(data_llm!$A:$A,"dddd",data_llm!$C:$C,$A61,data_llm!$F:$F,TRUE) | L61: =J61-K61 | M61: =IF(J61=0,"",ROUND(100*K61/J61,1)) | N61: =IF(F61=0,"",ROUND(E61*G61/F61,0))

Sheet udemy-top-down-shooter
A1: check | B1: severity | C1: title | D1: hits:udemy-top-down-shooter | E1: hits total | F1: adjudicated | G1: TP | H1: FP | I1: precision % | J1: LLM-only found | K1: overlap w/ script | L1: script misses | M1: script coverage % | N1: est. true hits
A2: arch-02 | B2: Major | C2: Use Case Depending on Framework Type | D2: =COUNTIFS(data_hits!$A:$A,"udemy-top-down-shooter",data_hits!$C:$C,$A2) | E2: =SUM(D2:D2) | F2: =G2+H2 | G2: =COUNTIFS(data_adj!$A:$A,"udemy-top-down-shooter",data_adj!$C:$C,$A2,data_adj!$E:$E,"TP") | H2: =COUNTIFS(data_adj!$A:$A,"udemy-top-down-shooter",data_adj!$C:$C,$A2,data_adj!$E:$E,"FP") | I2: =IF(F2=0,"",ROUND(100*G2/F2,1)) | J2: =COUNTIFS(data_llm!$A:$A,"udemy-top-down-shooter",data_llm!$C:$C,$A2) | K2: =COUNTIFS(data_llm!$A:$A,"udemy-top-down-shooter",data_llm!$C:$C,$A2,data_llm!$F:$F,TRUE) | L2: =J2-K2 | M2: =IF(J2=0,"",ROUND(100*K2/J2,1)) | N2: =IF(F2=0,"",ROUND(E2*G2/F2,0))
A3: arch-03 | B3: Major | C3: Domain Entity with ORM Annotations | D3: =COUNTIFS(data_hits!$A:$A,"udemy-top-down-shooter",data_hits!$C:$C,$A3) | E3: =SUM(D3:D3) | F3: =G3+H3 | G3: =COUNTIFS(data_adj!$A:$A,"udemy-top-down-shooter",data_adj!$C:$C,$A3,data_adj!$E:$E,"TP") | H3: =COUNTIFS(data_adj!$A:$A,"udemy-top-down-shooter",data_adj!$C:$C,$A3,data_adj!$E:$E,"FP") | I3: =IF(F3=0,"",ROUND(100*G3/F3,1)) | J3: =COUNTIFS(data_llm!$A:$A,"udemy-top-down-shooter",data_llm!$C:$C,$A3) | K3: =COUNTIFS(data_llm!$A:$A,"udemy-top-down-shooter",data_llm!$C:$C,$A3,data_llm!$F:$F,TRUE) | L3: =J3-K3 | M3: =IF(J3=0,"",ROUND(100*K3/J3,1)) | N3: =IF(F3=0,"",ROUND(E3*G3/F3,0))
A4: arch-05 | B4: Major | C4: Infrastructure Exception Leaking | D4: =COUNTIFS(data_hits!$A:$A,"udemy-top-down-shooter",data_hits!$C:$C,$A4) | E4: =SUM(D4:D4) | F4: =G4+H4 | G4: =COUNTIFS(data_adj!$A:$A,"udemy-top-down-shooter",data_adj!$C:$C,$A4,data_adj!$E:$E,"TP") | H4: =COUNTIFS(data_adj!$A:$A,"udemy-top-down-shooter",data_adj!$C:$C,$A4,data_adj!$E:$E,"FP") | I4: =IF(F4=0,"",ROUND(100*G4/F4,1)) | J4: =COUNTIFS(data_llm!$A:$A,"udemy-top-down-shooter",data_llm!$C:$C,$A4) | K4: =COUNTIFS(data_llm!$A:$A,"udemy-top-down-shooter",data_llm!$C:$C,$A4,data_llm!$F:$F,TRUE) | L4: =J4-K4 | M4: =IF(J4=0,"",ROUND(100*K4/J4,1)) | N4: =IF(F4=0,"",ROUND(E4*G4/F4,0))
A5: arch-08 | B5: Major | C5: Service Locator / Magic Container | D5: =COUNTIFS(data_hits!$A:$A,"udemy-top-down-shooter",data_hits!$C:$C,$A5) | E5: =SUM(D5:D5) | F5: =G5+H5 | G5: =COUNTIFS(data_adj!$A:$A,"udemy-top-down-shooter",data_adj!$C:$C,$A5,data_adj!$E:$E,"TP") | H5: =COUNTIFS(data_adj!$A:$A,"udemy-top-down-shooter",data_adj!$C:$C,$A5,data_adj!$E:$E,"FP") | I5: =IF(F5=0,"",ROUND(100*G5/F5,1)) | J5: =COUNTIFS(data_llm!$A:$A,"udemy-top-down-shooter",data_llm!$C:$C,$A5) | K5: =COUNTIFS(data_llm!$A:$A,"udemy-top-down-shooter",data_llm!$C:$C,$A5,data_llm!$F:$F,TRUE) | L5: =J5-K5 | M5: =IF(J5=0,"",ROUND(100*K5/J5,1)) | N5: =IF(F5=0,"",ROUND(E5*G5/F5,0))
A6: arch-09 | B6: Moderate | C6: Environment-Specific Branching in Business Logic | D6: =COUNTIFS(data_hits!$A:$A,"udemy-top-down-shooter",data_hits!$C:$C,$A6) | E6: =SUM(D6:D6) | F6: =G6+H6 | G6: =COUNTIFS(data_adj!$A:$A,"udemy-top-down-shooter",data_adj!$C:$C,$A6,data_adj!$E:$E,"TP") | H6: =COUNTIFS(data_adj!$A:$A,"udemy-top-down-shooter",data_adj!$C:$C,$A6,data_adj!$E:$E,"FP") | I6: =IF(F6=0,"",ROUND(100*G6/F6,1)) | J6: =COUNTIFS(data_llm!$A:$A,"udemy-top-down-shooter",data_llm!$C:$C,$A6) | K6: =COUNTIFS(data_llm!$A:$A,"udemy-top-down-shooter",data_llm!$C:$C,$A6,data_llm!$F:$F,TRUE) | L6: =J6-K6 | M6: =IF(J6=0,"",ROUND(100*K6/J6,1)) | N6: =IF(F6=0,"",ROUND(E6*G6/F6,0))
A7: arch-11 | B7: Moderate | C7: Environment Address Hardcoded in Code | D7: =COUNTIFS(data_hits!$A:$A,"udemy-top-down-shooter",data_hits!$C:$C,$A7) | E7: =SUM(D7:D7) | F7: =G7+H7 | G7: =COUNTIFS(data_adj!$A:$A,"udemy-top-down-shooter",data_adj!$C:$C,$A7,data_adj!$E:$E,"TP") | H7: =COUNTIFS(data_adj!$A:$A,"udemy-top-down-shooter",data_adj!$C:$C,$A7,data_adj!$E:$E,"FP") | I7: =IF(F7=0,"",ROUND(100*G7/F7,1)) | J7: =COUNTIFS(data_llm!$A:$A,"udemy-top-down-shooter",data_llm!$C:$C,$A7) | K7: =COUNTIFS(data_llm!$A:$A,"udemy-top-down-shooter",data_llm!$C:$C,$A7,data_llm!$F:$F,TRUE) | L7: =J7-K7 | M7: =IF(J7=0,"",ROUND(100*K7/J7,1)) | N7: =IF(F7=0,"",ROUND(E7*G7/F7,0))
A8: arch-12 | B8: Major | C8: Cache Key Lifecycle Mismatch | D8: =COUNTIFS(data_hits!$A:$A,"udemy-top-down-shooter",data_hits!$C:$C,$A8) | E8: =SUM(D8:D8) | F8: =G8+H8 | G8: =COUNTIFS(data_adj!$A:$A,"udemy-top-down-shooter",data_adj!$C:$C,$A8,data_adj!$E:$E,"TP") | H8: =COUNTIFS(data_adj!$A:$A,"udemy-top-down-shooter",data_adj!$C:$C,$A8,data_adj!$E:$E,"FP") | I8: =IF(F8=0,"",ROUND(100*G8/F8,1)) | J8: =COUNTIFS(data_llm!$A:$A,"udemy-top-down-shooter",data_llm!$C:$C,$A8) | K8: =COUNTIFS(data_llm!$A:$A,"udemy-top-down-shooter",data_llm!$C:$C,$A8,data_llm!$F:$F,TRUE) | L8: =J8-K8 | M8: =IF(J8=0,"",ROUND(100*K8/J8,1)) | N8: =IF(F8=0,"",ROUND(E8*G8/F8,0))
A9: clarity-06 | B9: Minor | C9: Noise Words in Names | D9: =COUNTIFS(data_hits!$A:$A,"udemy-top-down-shooter",data_hits!$C:$C,$A9) | E9: =SUM(D9:D9) | F9: =G9+H9 | G9: =COUNTIFS(data_adj!$A:$A,"udemy-top-down-shooter",data_adj!$C:$C,$A9,data_adj!$E:$E,"TP") | H9: =COUNTIFS(data_adj!$A:$A,"udemy-top-down-shooter",data_adj!$C:$C,$A9,data_adj!$E:$E,"FP") | I9: =IF(F9=0,"",ROUND(100*G9/F9,1)) | J9: =COUNTIFS(data_llm!$A:$A,"udemy-top-down-shooter",data_llm!$C:$C,$A9) | K9: =COUNTIFS(data_llm!$A:$A,"udemy-top-down-shooter",data_llm!$C:$C,$A9,data_llm!$F:$F,TRUE) | L9: =J9-K9 | M9: =IF(J9=0,"",ROUND(100*K9/J9,1)) | N9: =IF(F9=0,"",ROUND(E9*G9/F9,0))
A10: clarity-09 | B10: Moderate | C10: Complex Boolean Conditions Not Extracted | D10: =COUNTIFS(data_hits!$A:$A,"udemy-top-down-shooter",data_hits!$C:$C,$A10) | E10: =SUM(D10:D10) | F10: =G10+H10 | G10: =COUNTIFS(data_adj!$A:$A,"udemy-top-down-shooter",data_adj!$C:$C,$A10,data_adj!$E:$E,"TP") | H10: =COUNTIFS(data_adj!$A:$A,"udemy-top-down-shooter",data_adj!$C:$C,$A10,data_adj!$E:$E,"FP") | I10: =IF(F10=0,"",ROUND(100*G10/F10,1)) | J10: =COUNTIFS(data_llm!$A:$A,"udemy-top-down-shooter",data_llm!$C:$C,$A10) | K10: =COUNTIFS(data_llm!$A:$A,"udemy-top-down-shooter",data_llm!$C:$C,$A10,data_llm!$F:$F,TRUE) | L10: =J10-K10 | M10: =IF(J10=0,"",ROUND(100*K10/J10,1)) | N10: =IF(F10=0,"",ROUND(E10*G10/F10,0))
A11: clarity-16 | B11: Major | C11: Cyclomatic Complexity | D11: =COUNTIFS(data_hits!$A:$A,"udemy-top-down-shooter",data_hits!$C:$C,$A11) | E11: =SUM(D11:D11) | F11: =G11+H11 | G11: =COUNTIFS(data_adj!$A:$A,"udemy-top-down-shooter",data_adj!$C:$C,$A11,data_adj!$E:$E,"TP") | H11: =COUNTIFS(data_adj!$A:$A,"udemy-top-down-shooter",data_adj!$C:$C,$A11,data_adj!$E:$E,"FP") | I11: =IF(F11=0,"",ROUND(100*G11/F11,1)) | J11: =COUNTIFS(data_llm!$A:$A,"udemy-top-down-shooter",data_llm!$C:$C,$A11) | K11: =COUNTIFS(data_llm!$A:$A,"udemy-top-down-shooter",data_llm!$C:$C,$A11,data_llm!$F:$F,TRUE) | L11: =J11-K11 | M11: =IF(J11=0,"",ROUND(100*K11/J11,1)) | N11: =IF(F11=0,"",ROUND(E11*G11/F11,0))
A12: clarity-17 | B12: Moderate | C12: Function Length | D12: =COUNTIFS(data_hits!$A:$A,"udemy-top-down-shooter",data_hits!$C:$C,$A12) | E12: =SUM(D12:D12) | F12: =G12+H12 | G12: =COUNTIFS(data_adj!$A:$A,"udemy-top-down-shooter",data_adj!$C:$C,$A12,data_adj!$E:$E,"TP") | H12: =COUNTIFS(data_adj!$A:$A,"udemy-top-down-shooter",data_adj!$C:$C,$A12,data_adj!$E:$E,"FP") | I12: =IF(F12=0,"",ROUND(100*G12/F12,1)) | J12: =COUNTIFS(data_llm!$A:$A,"udemy-top-down-shooter",data_llm!$C:$C,$A12) | K12: =COUNTIFS(data_llm!$A:$A,"udemy-top-down-shooter",data_llm!$C:$C,$A12,data_llm!$F:$F,TRUE) | L12: =J12-K12 | M12: =IF(J12=0,"",ROUND(100*K12/J12,1)) | N12: =IF(F12=0,"",ROUND(E12*G12/F12,0))
A13: ddd-01 | B13: Major | C13: Value Object Mutability | D13: =COUNTIFS(data_hits!$A:$A,"udemy-top-down-shooter",data_hits!$C:$C,$A13) | E13: =SUM(D13:D13) | F13: =G13+H13 | G13: =COUNTIFS(data_adj!$A:$A,"udemy-top-down-shooter",data_adj!$C:$C,$A13,data_adj!$E:$E,"TP") | H13: =COUNTIFS(data_adj!$A:$A,"udemy-top-down-shooter",data_adj!$C:$C,$A13,data_adj!$E:$E,"FP") | I13: =IF(F13=0,"",ROUND(100*G13/F13,1)) | J13: =COUNTIFS(data_llm!$A:$A,"udemy-top-down-shooter",data_llm!$C:$C,$A13) | K13: =COUNTIFS(data_llm!$A:$A,"udemy-top-down-shooter",data_llm!$C:$C,$A13,data_llm!$F:$F,TRUE) | L13: =J13-K13 | M13: =IF(J13=0,"",ROUND(100*K13/J13,1)) | N13: =IF(F13=0,"",ROUND(E13*G13/F13,0))
... A61: tests-13 | B61: Critical | C61: Test Module Containing No Assertions | D61: =COUNTIFS(data_hits!$A:$A,"udemy-top-down-shooter",data_hits!$C:$C,$A61) | E61: =SUM(D61:D61) | F61: =G61+H61 | G61: =COUNTIFS(data_adj!$A:$A,"udemy-top-down-shooter",data_adj!$C:$C,$A61,data_adj!$E:$E,"TP") | H61: =COUNTIFS(data_adj!$A:$A,"udemy-top-down-shooter",data_adj!$C:$C,$A61,data_adj!$E:$E,"FP") | I61: =IF(F61=0,"",ROUND(100*G61/F61,1)) | J61: =COUNTIFS(data_llm!$A:$A,"udemy-top-down-shooter",data_llm!$C:$C,$A61) | K61: =COUNTIFS(data_llm!$A:$A,"udemy-top-down-shooter",data_llm!$C:$C,$A61,data_llm!$F:$F,TRUE) | L61: =J61-K61 | M61: =IF(J61=0,"",ROUND(100*K61/J61,1)) | N61: =IF(F61=0,"",ROUND(E61*G61/F61,0))

Sheet Files
A1: project | B1: path | C1: lines | D1: role | E1: stratum | F1: script hits | G1: processed
A2: archon-search | B2: /Users/manczg/Documents/development/archon-search/archon_search/pipeline.py | C2: 3635 | D2: prod | E2: top | F2: =COUNTIFS(data_hits!$B:$B,$B2) | G2: yes
A3: archon-search | B3: /Users/manczg/Documents/development/archon-search/archon_search/store.py | C3: 3105 | D3: prod | E3: top | F3: =COUNTIFS(data_hits!$B:$B,$B3) | G3: yes
A4: archon-search | B4: /Users/manczg/Documents/development/archon-search/archon_search/graph_store.py | C4: 2449 | D4: prod | E4: top | F4: =COUNTIFS(data_hits!$B:$B,$B4) | G4: yes
A5: archon-search | B5: /Users/manczg/Documents/development/archon-search/archon_search/server/mcp.py | C5: 2259 | D5: prod | E5: top | F5: =COUNTIFS(data_hits!$B:$B,$B5) | G5: yes
A6: archon-search | B6: /Users/manczg/Documents/development/archon-search/archon_search/eval/runner.py | C6: 2014 | D6: prod | E6: top | F6: =COUNTIFS(data_hits!$B:$B,$B6) | G6: yes
A7: archon-search | B7: /Users/manczg/Documents/development/archon-search/archon_search/parser.py | C7: 362 | D7: prod | E7: p25 | F7: =COUNTIFS(data_hits!$B:$B,$B7) | G7: yes
A8: archon-search | B8: /Users/manczg/Documents/development/archon-search/archon_search/embedder_cache.py | C8: 195 | D8: prod | E8: p50 | F8: =COUNTIFS(data_hits!$B:$B,$B8) | G8: yes
A9: archon-search | B9: /Users/manczg/Documents/development/archon-search/archon_search/sync_suppression.py | C9: 84 | D9: prod | E9: p75 | F9: =COUNTIFS(data_hits!$B:$B,$B9) | G9: yes
A10: archon-search | B10: /Users/manczg/Documents/development/archon-search/tests/test_store.py | C10: 8271 | D10: test | E10: top | F10: =COUNTIFS(data_hits!$B:$B,$B10) | G10: yes
A11: archon-search | B11: /Users/manczg/Documents/development/archon-search/tests/test_sync.py | C11: 5742 | D11: test | E11: top | F11: =COUNTIFS(data_hits!$B:$B,$B11) | G11: yes
A12: moonset | B12: /Users/manczg/Documents/development/moonset/moonset-app/MoonsetApp/Presentation/ViewModels/SleepTimerViewModel.swift | C12: 1003 | D12: prod | E12: top | F12: =COUNTIFS(data_hits!$B:$B,$B12) | G12: yes
A13: moonset | B13: /Users/manczg/Documents/development/moonset/moonset-app/MoonsetApp/Presentation/Views/SleepTimerView.swift | C13: 379 | D13: prod | E13: top | F13: =COUNTIFS(data_hits!$B:$B,$B13) | G13: yes
... A47: udemy-top-down-shooter | B47: /Users/manczg/Documents/development/udemy-top-down-shooter/Assets/LeftHandTargetTransform.cs | C47: 9 | D47: prod | E47: all | F47: =COUNTIFS(data_hits!$B:$B,$B47) | G47: yes

Sheet Method
A1: model | B1: sonnet (adjudication + LLM-only agents)
A2: run date | B2: 2026-08-26 (round-9 rerun, live round-8 scripts)
A3: execution | B3: collect.sh sweep upfront (all 46 files); then serial sonnet agents chunked by project (<=150 hits/agent): adjudicate + LLM-only -> rebuild xlsx
A4: adjudication sample | B4: all hits, every file (no per-check cap)
A5: script coverage % | B5: overlap / LLM-only found (recall proxy, formula)
A6: est. true hits | B6: hits total x precision (script haul corrected for FPs, formula)
A7: LLM-only repeats | B7: 1 (token budget; variance not measured)
A8: LLM-only input | B8: catalog of 60 scriptable checks (id/severity/title), hits withheld
A9: match tolerance | B9: same check + file, ±3 lines (data_llm.matched, computed at build time)
A10: HIT_CAP | B10: 200 (as shipped, per-file runs, no cap warnings observed unless noted)
A11: file selection | B11: files.tsv (frozen 2026-08-24)
A12: precision | B12: TP / adjudicated script hits (formula)
... A14: aggregates | B14: all counts are COUNTIFS/SUM formulas over data_hits/data_adj/data_llm

Sheet data_hits
A1: project | B1: file | C1: check | D1: line | E1: excerpt
A2: archon-search | B2: /Users/manczg/Documents/development/archon-search/archon_search/pipeline.py | C2: clarity-06 | D2: 95 | E2: class RagFusionSubQueryInfo:
A3: archon-search | B3: /Users/manczg/Documents/development/archon-search/archon_search/pipeline.py | C3: clarity-09 | D3: 1717 | E3: if k != "include_metadata" and v is not None and v is not False
A4: archon-search | B4: /Users/manczg/Documents/development/archon-search/archon_search/pipeline.py | C4: clarity-09 | D4: 1801 | E4: if rerank is False and len(collections) > 1 and self._reranker is not None:
A5: archon-search | B5: /Users/manczg/Documents/development/archon-search/archon_search/pipeline.py | C5: clarity-09 | D5: 864 | E5: if (
A6: archon-search | B6: /Users/manczg/Documents/development/archon-search/archon_search/pipeline.py | C6: clarity-09 | D6: 1059 | E6: if (
A7: archon-search | B7: /Users/manczg/Documents/development/archon-search/archon_search/pipeline.py | C7: clarity-09 | D7: 1960 | E7: if (
A8: archon-search | B8: /Users/manczg/Documents/development/archon-search/archon_search/pipeline.py | C8: clarity-09 | D8: 2672 | E8: if (
A9: archon-search | B9: /Users/manczg/Documents/development/archon-search/archon_search/pipeline.py | C9: clarity-09 | D9: 3457 | E9: if (
A10: archon-search | B10: /Users/manczg/Documents/development/archon-search/archon_search/pipeline.py | C10: clarity-16 | D10: 421 | E10: async def ingest_file(
A11: archon-search | B11: /Users/manczg/Documents/development/archon-search/archon_search/pipeline.py | C11: clarity-16 | D11: 888 | E11: async def ingest_directory(
A12: archon-search | B12: /Users/manczg/Documents/development/archon-search/archon_search/pipeline.py | C12: clarity-16 | D12: 1019 | E12: async def search(
A13: archon-search | B13: /Users/manczg/Documents/development/archon-search/archon_search/pipeline.py | C13: clarity-16 | D13: 1226 | E13: async def _search_graph_mode(
... A1812: udemy-top-down-shooter | B1812: /Users/manczg/Documents/development/udemy-top-down-shooter/Assets/LeftHandTargetTransform.cs | C1812: tests-01 | D1812: 5 | E1812: public class LeftHandTargetTransform : MonoBehaviour

Sheet data_adj
A1: project | B1: file | C1: check | D1: line | E1: verdict | F1: reason
A2: archon-search | B2: /Users/manczg/Documents/development/archon-search/archon_search/pipeline.py | C2: clarity-06 | D2: 95 | E2: TP | F2: class RagFusionSubQueryInfo uses noise-word Info suffix; not a framework-type exception
A3: archon-search | B3: /Users/manczg/Documents/development/archon-search/archon_search/pipeline.py | C3: clarity-09 | D3: 1717 | E3: FP | F3: continuation line of named dict-comprehension assignment filter_flags= — condition already carries a name
A4: archon-search | B4: /Users/manczg/Documents/development/archon-search/archon_search/pipeline.py | C4: clarity-09 | D4: 1801 | E4: TP | F4: 3-term if condition (rerank is False and len>1 and reranker is not None) not extracted
A5: archon-search | B5: /Users/manczg/Documents/development/archon-search/archon_search/pipeline.py | C5: clarity-09 | D5: 864 | E5: TP | F5: 4-term wrapped if condition not extracted into named predicate
A6: archon-search | B6: /Users/manczg/Documents/development/archon-search/archon_search/pipeline.py | C6: clarity-09 | D6: 1059 | E6: TP | F6: 4-term wrapped if condition (rag_fusion and ... and ...) not extracted
A7: archon-search | B7: /Users/manczg/Documents/development/archon-search/archon_search/pipeline.py | C7: clarity-09 | D7: 1960 | E7: TP | F7: 4-term wrapped if condition (rag_fusion and ... and ...) not extracted
